Workbook

Sheet README
A1: DecisionOS -> SaaS-Stable Tracker
A2: Sprint plan + Kanban board covering every fix from the backend, schema/scale, and AI/Brain reviews, ending in DevOps + Data Migration.
A3: Generated 2026-08-04 · Branch: Backend_optimization · Source docs: docs/BACKEND_SAAS_READINESS_REVIEW.md, docs/BACKEND_SCHEMA_SCALE_GOLIVE_REVIEW.md, docs/AI_BRAIN_AGENTIC_REVIEW.md
A5: How to use this workbook
A6: • | B6: Dashboard — live rollup of every sprint AND the Testing Plan: task counts, % complete, open P0s, and the overall go-live gate status. All formulas — edit Status on Task Backlog / Testing Plan and this updates itself.
A7: • | B7: Task Backlog — the single source of truth for engineering work. One row per fix. Change the Status dropdown as work moves; this drives the Dashboard and is the sortable/filterable 'sprint sheet.'
A8: • | B8: Kanban Board — visual board grouped by Sprint (the swimlanes), cards color-coded by Priority. Snapshot view for planning conversations; the Task Backlog is what you actually edit day to day.
A9: • | B9: Testing Plan — every test type required before going live (automated, multi-tenant isolation, security, load/performance, resilience, migration/backup) PLUS the Alpha -> Closed Beta -> Staged Beta -> GA rollout milestones with entry/exit criteria for each stage.
A10: • | B10: Go-Live Checklist — the final gate. Every row must be checked TRUE before opening self-serve signup or onboarding client #1 at scale — includes a line item confirming every Testing Plan phase passed.
A11: • | B11: RBAC & People Access — product-level audit of who-can-do-what. Companion to Sprint 2. Backlog items RBAC-01..30 also mirrored into Task Backlog under sprint 'Sprint 2.5' / 'Sprint 3' / 'Sprint 4' / 'Sprint 5'.
A13: Legend — Priority
A14: P0 | B14: Ship-blocker — must close before the next tenant / go-live gate it sits in
A15: P1 | B15: Fix before selling to a real customer — not an immediate blocker but close soon
A16: P2 | B16: Quality/hardening — schedule once P0/P1 are clear
A18: Legend — Status
A19: Backlog
A20: To Do
A21: In Progress
A22: Blocked
A23: In Review
A24: Done
A26: Cells to edit
A27: On Task Backlog: Status, Owner, Start Date, Due Date, and Notes are yours to fill in / update. On Testing Plan: Status and Owner are yours to update. On Go-Live Checklist: set Done? to TRUE only once verified. All editable columns are shown with a gold header fill. Everything else documents the finding and should not need editing.

Sheet Dashboard
B2: Go-Live Readiness Dashboard
B3: Everything below recalculates from Task Backlog — update Status there, not here.
B5: Total tasks | C5: =COUNTA('Task Backlog'!A2:A84)
B6: Done | C6: =COUNTIF('Task Backlog'!J2:J84,"Done")
B7: Overall % complete | C7: =IFERROR(C6/C5,0)
B8: Open P0s (all sprints) | C8: =COUNTIFS('Task Backlog'!F2:F84,"P0",'Task Backlog'!J2:J84,"<>Done")
B9: Go-Live blockers still open | C9: =COUNTIFS('Task Backlog'!N2:N84,"Yes",'Task Backlog'!J2:J84,"<>Done")
B10: Testing Plan phases not yet Passed | C10: =COUNTIF('Testing Plan'!I13:I33,"<>Passed")
B12: READY FOR 100-CLIENT SaaS? | C12: =IF(AND(C9=0,C10=0),"READY — all go-live blockers closed and every testing phase passed","NOT READY — "&C9&" blocker(s) open, "&C10&" testing phase(s) not yet Passed")
B14: Sprint | C14: Goal | D14: Gate? | E14: Total | F14: Done | G14: % Complete | H14: Open P0s
B15: Sprint 0 — Critical Security & Auth | C15: Close every exploit that would get the platform owned in week one. No external tenant before this is clear. | D15: GATE | E15: =COUNTIF('Task Backlog'!B2:B84,"Sprint 0") | F15: =COUNTIFS('Task Backlog'!B2:B84,"Sprint 0",'Task Backlog'!J2:J84,"Done") | G15: =IFERROR(F15/E15,0) | H15: =COUNTIFS('Task Backlog'!B2:B84,"Sprint 0",'Task Backlog'!F2:F84,"P0",'Task Backlog'!J2:J84,"<>Done")
B16: Sprint 1 — Scale & Operational Blockers | C16: Fix the operational issues that break under multiple replicas / real concurrent load. | D16: GATE | E16: =COUNTIF('Task Backlog'!B2:B84,"Sprint 1") | F16: =COUNTIFS('Task Backlog'!B2:B84,"Sprint 1",'Task Backlog'!J2:J84,"Done") | G16: =IFERROR(F16/E16,0) | H16: =COUNTIFS('Task Backlog'!B2:B84,"Sprint 1",'Task Backlog'!F2:F84,"P0",'Task Backlog'!J2:J84,"<>Done")
B17: Sprint 2 — Tenancy Hygiene & Data Integrity | C17: Harden tenant isolation edges and fix data-integrity rough spots found in the schema audit. | D17: Parallel | E17: =COUNTIF('Task Backlog'!B2:B84,"Sprint 2") | F17: =COUNTIFS('Task Backlog'!B2:B84,"Sprint 2",'Task Backlog'!J2:J84,"Done") | G17: =IFERROR(F17/E17,0) | H17: =COUNTIFS('Task Backlog'!B2:B84,"Sprint 2",'Task Backlog'!F2:F84,"P0",'Task Backlog'!J2:J84,"<>Done")
B18: Sprint 3 — Billing & Multi-Tenant AI Keys | C18: Stand up real billing and per-tenant AI cost isolation — required before charging money. | D18: GATE | E18: =COUNTIF('Task Backlog'!B2:B84,"Sprint 3") | F18: =COUNTIFS('Task Backlog'!B2:B84,"Sprint 3",'Task Backlog'!J2:J84,"Done") | G18: =IFERROR(F18/E18,0) | H18: =COUNTIFS('Task Backlog'!B2:B84,"Sprint 3",'Task Backlog'!F2:F84,"P0",'Task Backlog'!J2:J84,"<>Done")
B19: Sprint 4 — AI Brain / Agentic Enhancement | C19: Upgrade retrieval to real RAG and the Brain toward agentic. Parallel track — does not block go-live. | D19: Parallel | E19: =COUNTIF('Task Backlog'!B2:B84,"Sprint 4") | F19: =COUNTIFS('Task Backlog'!B2:B84,"Sprint 4",'Task Backlog'!J2:J84,"Done") | G19: =IFERROR(F19/E19,0) | H19: =COUNTIFS('Task Backlog'!B2:B84,"Sprint 4",'Task Backlog'!F2:F84,"P0",'Task Backlog'!J2:J84,"<>Done")
B20: Sprint 5 — DevOps, Deployment & Data Migration | C20: Final gate: staging, load test, observability, tested backups, migration plan, staged rollout, go/no-go. | D20: GATE | E20: =COUNTIF('Task Backlog'!B2:B84,"Sprint 5") | F20: =COUNTIFS('Task Backlog'!B2:B84,"Sprint 5",'Task Backlog'!J2:J84,"Done") | G20: =IFERROR(F20/E20,0) | H20: =COUNTIFS('Task Backlog'!B2:B84,"Sprint 5",'Task Backlog'!F2:F84,"P0",'Task Backlog'!J2:J84,"<>Done")

Sheet Task Backlog
A1: ID | B1: Sprint | C1: Category | D1: Task | E1: Fix / Description | F1: Priority | G1: Source Doc | H1: File Reference | I1: Effort (S/M/L) | J1: Status | K1: Owner | L1: Start Date | M1: Due Date | N1: Blocks Go-Live? | O1: Notes
A2: S0-01 | B2: Sprint 0 | C2: Security/Auth | D2: Remove hardcoded superadmin default credentials | E2: Require env vars for SUPERADMIN_EMAIL/PASSWORD; stop overwriting DB hash on every restart so rotation works | F2: P0 | G2: SaaS Readiness Review | H2: server.py:4925-4937 | I2: S | J2: Done | L2: 2026-08-11 | M2: 2026-08-11 | N2: Yes | O2: Shipped in FIX-006-A (c57b550).
A3: S0-02 | B3: Sprint 0 | C3: Security/Auth | D3: Fix CORS wildcard + credentials | E3: Replace allow_origin_regex='.*' with a strict origin allow-list; add CSRF protection for cookie-authed mutating routes | F3: P0 | G3: SaaS Readiness Review | H3: server.py:4994-5001, core.py:218-222 | I3: M | J3: Done | L3: 2026-08-12 | M3: 2026-08-12 | N3: Yes | O3: Shipped in FIX-006-B (ababc06).
A4: S0-03 | B4: Sprint 0 | C4: Security/Auth | D4: Auth-gate file downloads | E4: Add get_current_user + tenant ownership check to GET /api/files/{fname}; currently unauth, guessable UUID = any tenant's file | F4: P0 | G4: SaaS Readiness Review | H4: server.py:3032-3038 | I4: S | J4: Done | L4: 2026-08-12 | M4: 2026-08-12 | N4: Yes | O4: Shipped in FIX-006-C (685141d).
A5: S0-04 | B5: Sprint 0 | C5: Security/Auth | D5: Kill dev-mode OTP leak | E5: Stop returning dev_otp in the API response; hard-fail boot if no SMS provider configured when ENV=prod | F5: P0 | G5: SaaS Readiness Review | H5: server.py:1345-1347 | I5: S | J5: Done | L5: 2026-08-12 | M5: 2026-08-12 | N5: Yes | O5: Shipped in FIX-006-C (685141d).
A6: S0-05 | B6: Sprint 0 | C6: Security/Auth | D6: Fix WhatsApp signature bypass | E6: Reject the webhook request on HMAC mismatch instead of logging + processing anyway | F6: P0 | G6: SaaS Readiness Review | H6: server.py:3919-3933 | I6: S | J6: Done | L6: 2026-08-12 | M6: 2026-08-12 | N6: Yes | O6: Shipped in FIX-006-C (685141d).
A7: S0-06 | B7: Sprint 0 | C7: Security/Auth | D7: Rate-limit + captcha unauth AI endpoints | E7: Add Turnstile/hCaptcha + IP rate limit to /api/signup/* and /api/onboarding/* — currently unauth and can burn unlimited LLM spend | F7: P0 | G7: SaaS Readiness Review | H7: routers/signup.py, routers/onboarding.py:39,73 | I7: M | J7: Done | L7: 2026-08-12 | M7: 2026-08-12 | N7: Yes | O7: Shipped in FIX-006-D (93a9f1c).
A8: S0-07 | B8: Sprint 0 | C8: Security/Auth | D8: Add login rate limiting | E8: Tenant user login has no attempt lockout (admin login does); add 5-attempt/15-min lockout to match | F8: P1 | G8: SaaS Readiness Review | H8: routers/auth.py:151-162 | I8: S | J8: Done | L8: 2026-08-12 | M8: 2026-08-12 | N8: Yes | O8: Shipped in FIX-006-D (93a9f1c).
A9: S0-08 | B9: Sprint 0 | C9: Security/Auth | D9: Stop returning raw JWT in response body | E9: Login/register return the token in JSON as well as the cookie; any XSS bypasses HttpOnly. Cookie-only. | F9: P1 | G9: SaaS Readiness Review | H9: routers/auth.py:148,162 | I9: S | J9: Done | L9: 2026-08-11 | M9: 2026-08-11 | N9: Yes | O9: Shipped in FIX-006-A (c57b550).
A10: S0-09 | B10: Sprint 0 | C10: Security/Auth | D10: Split JWT secret: tenant vs platform admin | E10: Single JWT_SECRET used for both; only the 'type' claim separates them. Use two secrets. | F10: P1 | G10: SaaS Readiness Review | H10: core.py:237,297 | I10: S | J10: Done | L10: 2026-08-11 | M10: 2026-08-11 | N10: Yes | O10: Shipped in FIX-006-A (c57b550).
A11: S0-10 | B11: Sprint 0 | C11: Security/Auth | D11: Invalidate invite tokens after use | E11: Invite tokens never expire after first use; invite_start also bypasses OTP cooldown (SMS-bomb vector) and leaks full phone number in the response | F11: P1 | G11: SaaS Readiness Review | H11: server.py:1372,1386,1396,1397 | I11: S | J11: Done | L11: 2026-08-11 | M11: 2026-08-11 | N11: Yes | O11: Shipped in FIX-006-A (c57b550).
A12: S1-01 | B12: Sprint 1 | C12: Scale/Ops | D12: Externalize the follow-up scheduler | E12: In-process 300s loop triple-fires (duplicate emails/alerts) with 3 replicas, dies with 1. Move to a single external cron/worker or add leader election. | F12: P0 | G12: Schema/Scale/Go-Live Review | H12: server.py:2765, 4946 | I12: M | J12: Done | L12: 2026-08-09 | M12: 2026-08-09 | N12: Yes | O12: Shipped in FIX-002-D ((this commit)).
A13: S1-02 | B13: Sprint 1 | C13: Scale/Ops | D13: Index phone, drop Python-side filter | E13: OTP login + WhatsApp routing do a full collection scan with no phone index, capped at 2000-5000 docs (silent lockout beyond that). Add (tenant_id, phone) index. | F13: P0 | G13: Schema/Scale/Go-Live Review | H13: server.py:1357,1419,4004 | I13: S | J13: Done | L13: 2026-08-09 | M13: 2026-08-09 | N13: Yes | O13: Shipped in FIX-002-A (e21a9b3).
A14: S1-03 | B14: Sprint 1 | C14: Scale/Ops | D14: Move all uploads to obj_store | E14: Voice notes, meetings, ledger uploads write to local disk — lost on restart, invisible across replicas. Route everything through the existing obj_store path; delete the local /api/files path. | F14: P0 | G14: Schema/Scale/Go-Live Review | H14: server.py:1739,1902,3032; ledger.py:146 | I14: M | J14: Done | L14: 2026-08-09 | M14: 2026-08-09 | N14: Yes | O14: Shipped in FIX-002-E ((this commit)).
A15: S1-04 | B15: Sprint 1 | C15: Scale/Ops | D15: Commit real deployment config | E15: No Dockerfile/Procfile exists. Pin worker count, add graceful shutdown for in-flight LLM calls, request-size caps. | F15: P0 | G15: Schema/Scale/Go-Live Review | H15: (missing — new file) | I15: M | J15: Done | L15: 2026-08-09 | M15: 2026-08-09 | N15: Yes
A16: S1-05 | B16: Sprint 1 | C16: Scale/Ops | D16: Timeout + concurrency-limit LLM calls | E16: No asyncio.wait_for on LLM calls; one shared key across all tenants means a burst of voice-capture cascades 429s with no ceiling. Add timeout + semaphore. | F16: P1 | G16: Schema/Scale/Go-Live Review | H16: core.py:177 | I16: M | J16: Done | L16: 2026-08-09 | M16: 2026-08-09 | N16: Yes | O16: Shipped in FIX-002-B (6b6fc25).
A17: S1-06 | B17: Sprint 1 | C17: Scale/Ops | D17: Fix hardcoded purchase_payment key | E17: Owner-approval loop, pending-purchases dashboard, and payment-overdue alerts only recognize the textile pipeline key. Non-textile tenants silently lose their sign-off + payment tracking. | F17: P0 | G17: Schema/Scale/Go-Live Review | H17: routers/decisions.py:166; server.py:2429; routers/brief.py:95,98,238,262 | I17: M | J17: Done | L17: 2026-08-04 | M17: 2026-08-04 | N17: Yes | O17: Shipped in FIX-001-A (cb84474+69f4ce3).
A18: S2-01 | B18: Sprint 2 | C18: Tenancy/Data | D18: Add _ensure_owned() helper | E18: Many update_one/delete_* calls filter by {'id': X} only after an earlier tenant-scoped read. UUID makes it safe today but drift/leak risk. Centralize the pattern. | F18: P1 | G18: SaaS Readiness Review | H18: routers/tasks.py:317,360,395; decisions.py:144-227; brain_docs.py:320,329; ledger.py:585,638,684 | I18: M | J18: Done | L18: 2026-08-09 | M18: 2026-08-09 | N18: No | O18: Shipped in FIX-001-C (da29cfd).
A19: S2-02 | B19: Sprint 2 | C19: Tenancy/Data | D19: Complete TENANT_COLLECTIONS wipe | E19: Tenant deletion omits brain_context, brain_documents, capture_drafts, platform_alerts, reclassify_jobs, signup_sessions, and never deletes uploaded files. GDPR gap. | F19: P1 | G19: SaaS Readiness Review | H19: routers/admin.py:161-186 | I19: S | J19: Done | L19: 2026-08-04 | M19: 2026-08-04 | N19: No | O19: Shipped in FIX-001-E (65cea2c).
A20: S2-03 | B20: Sprint 2 | C20: Tenancy/Data | D20: Tenant-scope OTP + WhatsApp phone routing | E20: Two users in different tenants sharing a phone can log into the wrong workspace, or hijack another tenant's inbound WhatsApp. | F20: P0 | G20: Schema/Scale/Go-Live Review | H20: server.py:1418-1428,1357; 3999-4028 | I20: M | J20: Done | L20: 2026-08-09 | M20: 2026-08-09 | N20: Yes | O20: Shipped in FIX-003-A (6a1ecec).
A21: S2-04 | B21: Sprint 2 | C21: Tenancy/Data | D21: Fix cross-tenant WhatsApp log leak | E21: whatsapp/logs OR-includes tenant_id:None rows, visible to every tenant owner. | F21: P1 | G21: SaaS Readiness Review | H21: server.py:3993-3995 | I21: S | J21: Done | L21: 2026-08-09 | M21: 2026-08-09 | N21: No | O21: Shipped in FIX-003-A (6a1ecec).
A22: S2-05 | B22: Sprint 2 | C22: Tenancy/Data | D22: Fix unfiltered enrich_decisions fetch | E22: Related tasks/users fetched with no tenant filter; safe only because task_ids can't currently contain a foreign UUID. | F22: P2 | G22: SaaS Readiness Review | H22: server.py:2142-2158; routers/decisions.py:44,172-175 | I22: S | J22: Done | L22: 2026-08-10 | M22: 2026-08-10 | N22: No | O22: Shipped in FIX-003-B (f18bbc3).
A23: S2-06 | B23: Sprint 2 | C23: Tenancy/Data | D23: Add session invalidation on logout/password-change | E23: JWT stays valid 7 days after logout; no jti/token-version, so a stolen session can't be revoked. | F23: P1 | G23: SaaS Readiness Review | H23: core.py:225-226 | I23: M | J23: Done | L23: 2026-08-10 | M23: 2026-08-10 | N23: No | O23: Shipped in FIX-003-C (f48bd24).
A24: S2-07 | B24: Sprint 2 | C24: Tenancy/Data | D24: Add email verification + password reset | E24: No self-serve recovery flow exists anywhere; enterprise-deal blocker. | F24: P1 | G24: SaaS Readiness Review | H24: routers/auth.py | I24: M | J24: Done | L24: 2026-08-10 | M24: 2026-08-10 | N24: No | O24: Shipped in FIX-003-D (4ef865e).
A25: S2-08 | B25: Sprint 2 | C25: Tenancy/Data | D25: Fix dead contacts.kind index | E25: Index uses 'kind', every read/write uses 'type'. Index (tenant_id, type) instead. | F25: P1 | G25: Schema/Scale/Go-Live Review | H25: server.py:4865 | I25: S | J25: Done | L25: 2026-08-10 | M25: 2026-08-10 | N25: No | O25: Shipped in FIX-003-B (f18bbc3).
A26: S2-09 | B26: Sprint 2 | C26: Tenancy/Data | D26: Fix denormalized-name staleness | E26: assignee_role / contact_name copies go stale on rename and are shown to users. Add refresh-on-rename. | F26: P2 | G26: Schema/Scale/Go-Live Review | H26: routers/tasks.py; server.py:3326 | I26: S | J26: Done | L26: 2026-08-10 | M26: 2026-08-10 | N26: No | O26: Shipped in FIX-003-C (f48bd24).
A27: S2-10 | B27: Sprint 2 | C27: Tenancy/Data | D27: Handle concurrent-registration race | E27: Same-email concurrent registers can race past the pre-check and hit the unique index, throwing a raw 500 instead of a clean 400. | F27: P2 | G27: Schema/Scale/Go-Live Review | H27: routers/auth.py:92-93 | I27: S | J27: Done | L27: 2026-08-10 | M27: 2026-08-10 | N27: No | O27: Shipped in FIX-003-B (f18bbc3).
... A29: S2-12 | B29: Sprint 2 | C29: Tenancy/Data | D29: Fix 'active workflows' hardcoded terminal stages | E29: KPI checks stage NOT IN [delivered, paid] — non-textile terminal stages never match, so the count only ever climbs. | F29: P2 | G29: Schema/Scale/Go-Live Review | H29: server.py:2433 | I29: S | J29: Done | L29: 2026-08-10 | M29: 2026-08-10 | N29: No | O29: Already closed by FIX-001-F; regression-guarded in FIX-003-B.
A30: S3-01 | B30: Sprint 3 | C30: Billing/AI-Keys | D30: Integrate real billing (Stripe or Razorpay) | E30: stripe is in requirements.txt but never imported. No subscription billing exists at all today. | F30: P0 | G30: SaaS Readiness Review | H30: requirements.txt:129 | I30: L | J30: Backlog | N30: Yes
A31: S3-02 | B31: Sprint 3 | C31: Billing/AI-Keys | D31: Add plan / entitlement fields to tenant doc | E31: No plan, trial_ends_at, seat_limit, or feature_flags — every tenant is on unlimited free forever. | F31: P1 | G31: SaaS Readiness Review | H31: tenant document schema | I31: M | J31: Done | L31: 2026-08-10 | M31: 2026-08-10 | N31: Yes | O31: Shipped in FIX-005-A (afbf9b8).
A32: S3-03 | B32: Sprint 3 | C32: Billing/AI-Keys | D32: Per-tenant AI key resolver | E32: All AI keys are one global pool shared by every tenant; one rate-limited/leaked key breaks 100% of tenants. Add per-tenant key columns + fallback resolver. | F32: P0 | G32: SaaS Readiness Review | H32: config.py:53-60; core.py:177-205; routers/admin.py:335-348 | I32: L | J32: Done | L32: 2026-08-10 | M32: 2026-08-10 | N32: Yes | O32: Shipped in FIX-005-A (afbf9b8).
A33: S3-04 | B33: Sprint 3 | C33: Billing/AI-Keys | D33: Enforce usage quotas (402 on exceed) | E33: Usage telemetry is estimation-only; no hard limit stops a tenant from running up unlimited LLM cost. | F33: P1 | G33: SaaS Readiness Review | H33: services/usage.py | I33: M | J33: Done | L33: 2026-08-10 | M33: 2026-08-10 | N33: Yes | O33: Shipped in FIX-005-B (29d2238).
A34: S4-01 | B34: Sprint 4 | C34: AI/Brain | D34: Fix text-index stemming + index db.memory | E34: default_language='none' disables stemming (refund != refunds); db.memory has no text index at all, only regex scan. | F34: P2 | G34: AI/Brain/Agentic Review | H34: server.py:4894; brain.py:250-255 | I34: S | J34: Backlog | N34: No
A35: S4-02 | B35: Sprint 4 | C35: AI/Brain | D35: Fix task-done Brain write-coverage gap + link provenance | E35: Execution-plan-complete path skips record_context; add decision_id linkage so decision->task->outcome is reconstructable. | F35: P1 | G35: AI/Brain/Agentic Review | H35: tasks.py:507; services/brain_context.py | I35: M | J35: Backlog | N35: No
A36: S4-03 | B36: Sprint 4 | C36: AI/Brain | D36: Rename brain_contexts -> brain_query_cache | E36: Kills the dangerous brain_context / brain_contexts name collision. | F36: P2 | G36: AI/Brain/Agentic Review | H36: brain.py:714,752,794 | I36: S | J36: Backlog | N36: No
A37: S4-04 | B37: Sprint 4 | C37: AI/Brain | D37: Unify /ask and /brain/agent retrieval reach | E37: /ask never reads brain_context or brain_documents — provenance answers only work on the Dex agent path. Give both the same reach. | F37: P1 | G37: AI/Brain/Agentic Review | H37: routers/brain.py:52,205 | I37: M | J37: Backlog | N37: No
A38: S4-05 | B38: Sprint 4 | C38: AI/Brain | D38: Extract + chunk + embed documents at ingest | E38: Uploaded documents are stored as metadata only; body text is never read at ingest. Add server-side extraction + chunking + embeddings into a new brain_chunks collection. | F38: P1 | G38: AI/Brain/Agentic Review | H38: routers/brain_docs.py:147-213 | I38: L | J38: Backlog | N38: No
A39: S4-06 | B39: Sprint 4 | C39: AI/Brain | D39: Adopt vector search + hybrid retrieval | E39: Move from keyword-only BM25/regex to embeddings (Atlas Vector Search if on Atlas, else Qdrant/pgvector) fused with existing text search. | F39: P1 | G39: AI/Brain/Agentic Review | H39: (new infra) | I39: L | J39: Backlog | N39: No
A40: S4-07 | B40: Sprint 4 | C40: AI/Brain | D40: Formalize a tool registry | E40: The 10 _compute_* + 4 _tool_* handlers already have a clean typed contract — wrap in Pydantic in/out models and register centrally. | F40: P2 | G40: AI/Brain/Agentic Review | H40: routers/brain.py; routers/brain_router.py | I40: M | J40: Backlog | N40: No
A41: S4-08 | B41: Sprint 4 | C41: AI/Brain | D41: Add bounded planner-executor loop + native function-calling | E41: /brain/agent is single-turn (plan -> fan-out -> synthesize, no re-plan). Add an observe-then-replan loop and migrate to Anthropic tools=[...]. | F41: P2 | G41: AI/Brain/Agentic Review | H41: routers/brain_router.py:266-277,481-482 | I41: L | J41: Backlog | N41: No
...

Sheet Fix Log
A1: Fix Log — every change we make, in order
A2: Running record. Updated side-by-side after every shipped commit. Currently: 11 Done, 13 in backlog.
A4: Modules
A5: Module | B5: Name | C5: What it delivers | D5: Priority | E5: Status
A6: Module 1 | B6: Multi-tenant / Dynamic Workflows | C6: DONE. 6 fixes shipped: dynamic per-tenant workflow approval, workflow<->Finance link, tenant-scoped safety helpers, onboarding drafts + AI status tracking, complete tenant deletion (DPDP/GDPR), dynamic terminal stages. Non-textile tenants get their full lifecycle end-to-end. | D6: P0 for selling to any small business that isn't a textile manufacturer. | E6: 6/6 shipped.
A7: Module 2 | B7: Sprint 1 — Scale & Ops | C7: DONE. 6 fixes shipped: phone index (kills full-collection scans), LLM timeouts + concurrency semaphore, migration ledger, distributed leader lock (multi-replica-safe scheduler), obj_store for all uploads, and Dockerfile + Procfile with production-grade signal handling + healthcheck. | D7: Turns 'runs in Sharma demo' into 'survives 100 tenants under real load.' | E7: 6/6 shipped. Sprint 1 COMPLETE.
A8: Module 3 | B8: Sprint 2 – Tenancy & Data | C8: DONE. 12/12 shipped: tenant helpers (FIX-001-C), TENANT_COLLECTIONS wipe (FIX-001-E), OTP+WhatsApp tenant scoping (FIX-003-A), hygiene batch (FIX-003-B), JWT revocation + contact rename + AI regen status (FIX-003-C), email verification + password reset (FIX-003-D). | D8: P0 tenancy bugs closed. Remaining are hardening (session invalidation, email verification, dead index cleanup, denormalized-name staleness) — not blockers for a controlled beta but recommended before wider rollout. | E8: 12/12 shipped. Sprint 2 COMPLETE.
A9: Fix Log entries
A10: Fix ID | B10: Module | C10: Backlog ID | D10: Title | E10: Description | F10: Files touched | G10: Related tests | H10: Status | I10: Priority | J10: Started | K10: Finished | L10: PR / Commit | M10: Notes / gotchas
A11: FIX-001-A | B11: Multi-tenant / Dynamic Workflows | C11: S1-06 | D11: Kill purchase_payment textile hardcode | E11: Owner-approval loop + dashboard + payment-overdue alerts filtered on the literal 'purchase_payment' string — silently broke for non-textile tenants. Fix uses per-tenant pipeline lookup. | F11: routers/decisions.py:166; server.py:2429; routers/brief.py:95,98,238,262 | G11: tests/test_workflows_dynamic.py — 19 tests | H11: Done | I11: P0 | J11: 2026-08-04 | K11: 2026-08-04 | L11: cb84474 + 69f4ce3 | M11: First unblock for selling to any small business that isn't a manufacturer.
A12: FIX-001-B | B12: Multi-tenant / Dynamic Workflows | C12: (discovered mid-fix) | D12: Wire workflow -> Finance auto-expense on procurement completion | E12: Workflow terminal-stage advance auto-creates a pending-bill expense in Finance linked to the workflow. Notifies finance role. Idempotent, fire-and-forget. | F12: server.py:2236; routers/ledger.py:222 | G12: tests/test_workflow_finance_link.py — 17 tests | H12: Done | I12: P1 | J12: 2026-08-04 | K12: 2026-08-09 | L12: 98d0291 | M12: Founder no longer records purchases twice. Bill upload -> OCR promotion flow is a follow-up.
A13: FIX-001-C | B13: Multi-tenant / Data Integrity | C13: S2-01 | D13: Add tenant-scoped safety helpers (_ensure_owned) | E13: Every update_one/delete_* now routed through services/tenancy.py::tenant_filter() which pins BOTH id AND tenant_id. Python TypeError blocks smuggling different tenant_id via extras. | F13: services/tenancy.py (new); ~25 sites across routers + server.py | G13: tests/test_tenancy_helpers.py — 16 tests | H13: Done | I13: P1 | J13: 2026-08-04 | K13: 2026-08-09 | L13: da29cfd | M13: Grep found 25+ sites vs. audit's 13. Discipline lesson: always grep AFTER refactor.
A14: FIX-001-D | B14: Multi-tenant / Onboarding | C14: S1-04 partial + new | D14: Onboarding drafts + AI status tracking + retry endpoint | E14: Two gaps closed: silent AI degradation (ai_setup_status per generator + regenerate endpoint) and data loss on failure (onboarding_drafts persist each wizard step). | F14: services/ai_setup.py + services/onboarding_drafts.py (new); +5 endpoints | G14: tests/test_onboarding_flow.py — 27 tests | H14: Done | I14: P1 | J14: 2026-08-09 | K14: 2026-08-09 | L14: 3bc0059 | M14: Idempotent-register (Comprehensive-scope 3e) and onboarding_drafts TTL deferred.
A15: FIX-001-E | B15: Multi-tenant / Data Integrity | C15: S2-02 | D15: Complete TENANT_COLLECTIONS wipe + file deletion (DPDP/GDPR) | E15: TENANT_COLLECTIONS grown to 30 (was missing brain_context + brain_documents). Now also iterates db.files and deletes each object from storage before wiping. | F15: routers/admin.py; services/obj_store.py::delete_object (new) | G15: tests/test_tenant_deletion.py — 8 tests (incl. drift-detection) | H15: Done | I15: P1 | J15: 2026-08-04 | K15: 2026-08-04 | L15: 65cea2c | M15: Legacy local-disk files depend on Sprint 1 S1-03 to move all uploads to obj_store.
A16: FIX-001-F | B16: Multi-tenant / Dynamic Workflows | C16: WF-3 | D16: Dynamic pipeline terminal stages ('active workflows' stops climbing forever) | E16: 4 places hardcoded ['delivered','paid'] as terminal stages. New services/workflows.py::all_terminal_stages(om) + legacy hedge. All 4 sites now use dynamic exclusion. | F16: services/workflows.py; server.py:2500, :3697, :3745, :3911 | G16: tests/test_workflows_dynamic.py — 12 additional tests | H16: Done | I16: P2 | J16: 2026-08-09 | K16: 2026-08-09 | L16: 8235c61 | M16: Calendar deliveries also hardcodes pipeline TYPES - see FIX-FUP-09.
A17: FIX-002-A | B17: Sprint 1 / Scale & Ops | C17: S1-02 | D17: Phone index + kill full-collection scans on OTP + WhatsApp routing | E17: 3 hot paths (OTP request, OTP verify, resolve_wa_tenant) ran full-collection scans over db.users on every call, capped at 2000/5000 users (silent lockout beyond). Fix indexes new phone_norm field; hot paths become exact-match lookups. Bootstrap includes idempotent backfill for existing users. | F17: services/phone.py (new); server.py bootstrap + 3 hot paths; routers/auth.py; routers/team.py | G17: tests/test_phone_indexed_lookup.py — 16 tests (parity, query shape, no-cap guard) | H17: Done | I17: P0 | J17: 2026-08-09 | K17: 2026-08-09 | L17: e21a9b3 | M17: Existing OTP hashes still verify (parity-tested). server.py:4623 (per-tenant scan) noted but out of scope.
A18: FIX-002-B | B18: Sprint 1 / Scale & Ops | C18: S1-05 | D18: LLM call timeouts + concurrency semaphore | E18: One shared Anthropic key + no timeout + no concurrency cap = 50 concurrent voice captures cascade into 429s and unbounded latency. New services/llm_limits.py::guarded_llm wraps every LLM call with asyncio.wait_for + shared semaphore. Covers _ResilientChat + 4 direct LlmChat sites. | F18: services/llm_limits.py (new); core.py::_ResilientChat; server.py (2 Gemini); routers/admin.py; routers/ledger.py | G18: tests/test_llm_limits.py — 14 tests (peak-concurrency, timeout-releases-slot, exception-releases-slot) | H18: Done | I18: P1 | J18: 2026-08-09 | K18: 2026-08-09 | L18: 6b6fc25 | M18: Per-process only. Cross-process rate limiting needs Redis (Sprint 3 with per-tenant keys). STT paths (Whisper/Sarvam) NOT wrapped - separate follow-up.
A19: FIX-002-C | B19: Sprint 1 / Scale & Ops | C19: (new: raised during Q&A) | D19: Migration ledger for MongoDB schema changes | E19: Ad-hoc bootstrap migrations are fine for additive changes (new fields, new indexes, safe backfills) but unsafe the moment we ship a destructive migration (rename+copy+delete, data reshape). Add db.migrations_applied collection + a migrate(name, fn) helper so migrations run exactly once and non-idempotent changes are safe. | F19: services/migrations.py (new); server.py bootstrap block | G19: tests/test_migrations.py — helper contract + idempotency | H19: Done | I19: P1 | J19: 2026-08-09 | K19: 2026-08-09 | L19: (this commit) | M19: Prerequisite for S1-03 (uploads migration). MongoDB doesn't need Alembic (no DDL) but does need this ledger discipline.
A20: FIX-002-D | B20: Sprint 1 / Scale & Ops | C20: S1-01 | D20: Externalize the follow-up scheduler (multi-replica safe) | E20: In-process 300s loop triple-fires with 3 replicas (duplicate emails/alerts), dies with 1. Options: (a) external cron + endpoint (b) in-process with distributed leader election. Design decision needed. | F20: server.py:2765 (scheduler loop); new endpoint or external cron config | G20: tests: single-fire under multiple simulated replicas | H20: Done | I20: P0 | J20: 2026-08-09 | K20: 2026-08-09 | L20: (this commit) | M20: Half-day fix. Requires design decision on external cron vs leader election.
A21: FIX-002-E | B21: Sprint 1 / Scale & Ops | C21: S1-03 | D21: Migrate all uploads to obj_store (kill local-disk file storage) | E21: Voice notes, meetings, ledger uploads write to local UPLOAD_DIR — lost on restart, invisible across replicas. Route everything through obj_store with tenant-prefixed paths; delete local /api/files path. Includes migration for existing local-disk records. | F21: server.py:1739,1902,3032; ledger.py:146; obj_store integration in all 3 paths | G21: tests: upload, download, cross-replica visibility, deletion | H21: Done | I21: P0 | J21: 2026-08-09 | K21: 2026-08-09 | L21: (this commit) | M21: Half-day. Depends on FIX-002-C for the migration. Also closes FIX-001-E EC8 (legacy local files for tenant deletion).
A22: FIX-002-F | B22: Sprint 1 / Scale & Ops | C22: S1-04 | D22: Commit real Dockerfile + Procfile with pinned worker count + graceful shutdown | E22: No Dockerfile exists (only .emergent/emergent.yml base-image pointer). Need a real deployable Dockerfile with worker count pinned, graceful shutdown for in-flight LLM work, request-size caps. | F22: backend/Dockerfile (new); backend/Procfile (new); backend/.dockerignore (new) | G22: tests/test_dockerfile.py - 25 static contract tests (multi-stage, non-root, healthcheck, secrets, apt cleanup, Procfile parity) | H22: Done | I22: P0 | J22: 2026-08-09 | K22: 2026-08-09 | L22: 5a4644e | M22: Multi-stage Python 3.12-slim build. Non-root user, HEALTHCHECK via Python stdlib on /api/health, tini as PID 1, --timeout-graceful-shutdown 60 (> 45s LLM cap from FIX-002-B). emergentintegrations installed from Emergent's CDN (regression guard: without extra-index-url, requirements install silently drops that package). Docker build not exercised in tests - daemon unavailable in this env; static tests cover structure + security. FIX-FUP-15 logged to wire docker build into CI. SPRINT 1 COMPLETE with this ship.
A23: FIX-FUP-01 | B23: Follow-up (from FIX-001-A) | C23: (logged during A) | D23: Delete WORKFLOW_OWNER_ROLE dead code | E23: server.py:212 defines WORKFLOW_OWNER_ROLE dict - nothing references it. | F23: server.py:212 | G23: test: import check + grep for zero refs | H23: Not Started | I23: P2 | M23: Dead code cleanup.
A24: FIX-FUP-02 | B24: Follow-up (from FIX-001-A) | C24: (logged during A) | D24: Clean 'purchase_payment' from AI onboarding prompt | E24: server.py:1094,1103 - operating-model AI prompt uses 'purchase_payment' as an example. Could bias AI toward textile key. | F24: server.py:1094, 1103 | G24: test: onboard non-textile tenant, assert no 'purchase_payment' in operating_model | H24: Not Started | I24: P2 | M24: Prevents textile leak from re-emerging via the prompt.
A25: FIX-FUP-03 | B25: Follow-up (from FIX-001-A) | C25: (logged during A) | D25: Memoize tenant_procurement_pipeline in brief.py | E25: Called TWICE per brief request (counter + drill-down). Minor inefficiency. | F25: routers/brief.py | G25: test: mock tenant_operating_model, assert called once | H25: Not Started | I25: P2 | M25: Small perf tidy.
A26: FIX-FUP-04 | B26: Follow-up (from FIX-001-B) | C26: (logged during B) | D26: Unique index on expenses.(tenant_id, workflow_id) | E26: Check + insert is not atomic. Rare race could double-create. Close with unique compound index. | F26: server.py bootstrap | G26: test: concurrent create_expense with same workflow_id | H26: Not Started | I26: P2 | M26: Belt-and-braces for FIX-001-B idempotency.
A27: FIX-FUP-05 | B27: Follow-up (from FIX-001-B) | C27: (logged during B) | D27: Bill upload -> OCR promotion flow (Finance side) | E27: Complete the story: Finance uploads bill, OCR extracts real amount, expense flips from awaiting_bill to reconciled. | F27: routers/ledger.py + existing OCR pipeline | G27: test: mock OCR + upload + status transition | H27: Not Started | I27: P1 | M27: One-click reconciliation finish for FIX-001-B.
A28: FIX-FUP-06 | B28: Follow-up (from FIX-001-C) | C28: (logged during C) | D28: 'id' footgun in tenant_filter | E28: Extras can overwrite id (though tenant scope still holds). Documented in tests; stricter version would reject. | F28: services/tenancy.py | G28: test already documents | H28: Not Started | I28: P2 | M28: Cosmetic hardening.
A29: FIX-FUP-07 | B29: Follow-up (from FIX-001-D) | C29: (logged during D) | D29: TTL index on onboarding_drafts | E29: Auto-expire ~30 days after last update. Bootstrap: create_index('updated_at', expireAfterSeconds=30*86400). | F29: server.py bootstrap | G29: test: verify index exists | H29: Not Started | I29: P2 | M29: Small bootstrap tweak.
A30: FIX-FUP-08 | B30: Follow-up (from FIX-001-D) | C30: (logged during D) | D30: Idempotent register by draft_id (Comprehensive-scope 3e) | E30: Network drop mid-register -> user retries -> 'Email already registered' 400. Fix: if draft completed with tenant_id, return existing session on retry. | F30: routers/auth.py::register | G30: test: register with draft_id twice, second returns existing tenant | H30: Not Started | I30: P1 | M30: Closes the last onboarding-flow paper cut.
A31: FIX-FUP-09 | B31: Follow-up (from FIX-001-F) | C31: (logged during F) | D31: tenant_sales_pipeline resolver (mirror of procurement) | E31: Calendar deliveries hardcodes pipeline TYPES ['distribution','sales_dispatch']. Add resolver like tenant_procurement_pipeline. | F31: services/workflows.py; calendar endpoint | G31: tests: bakery order_fulfilment shows in calendar deliveries | H31: Not Started | I31: P2 | M31: Extends FIX-001-A pattern to sales side.
A32: FIX-FUP-10 | B32: Follow-up (from FIX-002-A) | C32: (logged during 002-A) | D32: phone_norm on WhatsApp review UI + contact lookups | E32: server.py:4623 builds a phone_index for the WA review UI via Python-side normalization. Tenant-scoped (not a P0 like the global hot paths) but same pattern. | F32: server.py:4623 area | G32: test: query uses phone_norm | H32: Not Started | I32: P2 | M32: Consistency win, not a P0.
A33: FIX-FUP-11 | B33: Follow-up (from FIX-002-B) | C33: (logged during 002-B) | D33: Guard STT (Whisper/Sarvam) paths with llm_limits | E33: The FIX-002-B semaphore/timeout covers LlmChat paths. STT goes through OpenAISpeechToText and Sarvam wrappers separately - not yet guarded. | F33: server.py transcribe_audio_full and Sarvam wrapper | G33: test: mock STT, assert guarded_llm called | H33: Not Started | I33: P2 | M33: ~1 hour when someone hits an STT rate limit.
A34: FIX-FUP-12 | B34: Follow-up (from FIX-002-B) | C34: (logged during 002-B) | D34: Cross-process LLM rate limiting (Redis-backed) | E34: Semaphore is per-process. With multiple uvicorn workers, total in-flight = workers x cap. Ties to Sprint 3 (per-tenant AI keys) so per-tenant caps become meaningful. | F34: new services/llm_limits.py extension + Redis | G34: test: distributed semaphore behavior | H34: Not Started | I34: P1 | M34: Sprint 3 territory.
A35: FIX-FUP-13 | B35: Follow-up (from FIX-002-F) | C35: (logged during 002-F local run) | D35: Frontend install hardening: legacy-peer-deps | E35: npm install silently exited 0 with 0 packages because react-day-picker@8 peer-requires date-fns@^2||^3 but this project uses date-fns@4. Added frontend/.npmrc with legacy-peer-deps=true so every dev + CI `npm install` runs without needing --legacy-peer-deps flag. | F35: frontend/.npmrc (new) | G35: manual: npm install now completes (was silent 0-package exit) | H35: Done | I35: P0 | J35: 2026-08-09 | K35: 2026-08-09 | L35: 5a4644e | M35: The trap that blocked our first local frontend boot. Locked in as .npmrc so it doesn't happen again.
A36: FIX-FUP-14 | B36: Follow-up (from FIX-002-F) | C36: (logged during 002-F local run) | D36: Pin ajv@^8.20.0 across the tree (webpack crash fix) | E36: ajv-keywords@5 needs `ajv/dist/compile/codegen` (ajv v8), but a nested dep resolved ajv@6, causing webpack to crash on start with `Cannot find module ajv/dist/compile/codegen`. Added overrides.ajv (npm) + resolutions.ajv (yarn) both set to ^8.20.0 to force v8 across the dep tree. | F36: frontend/package.json (overrides + resolutions blocks) | G36: manual: npm ls ajv shows ajv@8.20.0 at root + ajv-keywords@5.1.0 -> ajv@8 deduped | H36: Done | I36: P0 | J36: 2026-08-09 | K36: 2026-08-09 | L36: 5a4644e | M36: Value must match the direct dep pinning exactly (^8.20.0) or npm throws EOVERRIDE. Learned that mid-fix.
A37: Status legend:
A38: Not Started | B38: In backlog, no work yet
A39: Planning | B39: Reading code, scoping the fix, drafting approach
A40: In Progress | B40: Writing the fix
A41: Code Review | B41: Fix written, awaiting review / self-review
...

Sheet Kanban Board
A1: Roadmap Kanban Board — swimlanes = Sprints, cards color-coded by Priority
A2: Snapshot view for planning. To track day-to-day status changes, edit the Task Backlog tab.
A4: Sprint 0 Critical Security & Auth (GATE) | B4: Sprint 1 Scale & Operational Blockers (GATE) | C4: Sprint 2 Tenancy Hygiene & Data Integrity (parallel) | D4: Sprint 3 Billing & Multi-Tenant AI Keys (GATE) | E4: Sprint 4 AI Brain / Agentic Enhancement (parallel) | F4: Sprint 5 DevOps, Deployment & Data Migration (GATE)
A5: [S0-01] Remove hardcoded superadmin default credentials (Security/Auth) | B5: [DONE][S1-01] Externalize the follow-up scheduler (Scale/Ops) | C5: [DONE][S2-01] Add _ensure_owned() helper (Tenancy/Data) | D5: [S3-01] Integrate real billing (Stripe or Razorpay) (Billing/AI-Keys) | E5: [S4-01] Fix text-index stemming + index db.memory (AI/Brain) | F5: [S5-01] Stand up a staging environment (DevOps/Migration)
A6: [S0-02] Fix CORS wildcard + credentials (Security/Auth) | B6: [DONE][S1-02] Index phone, drop Python-side filter (Scale/Ops) | C6: [DONE][S2-02] Complete TENANT_COLLECTIONS wipe (Tenancy/Data) | D6: [DONE][S3-02] Add plan / entitlement fields to tenant doc (Billing/AI-Keys) | E6: [S4-02] Fix task-done Brain write-coverage gap + link provenance (AI/Brain) | F6: [S5-02] Run a load test at target scale (DevOps/Migration)
A7: [S0-03] Auth-gate file downloads (Security/Auth) | B7: [DONE][S1-03] Move all uploads to obj_store (Scale/Ops) | C7: [DONE][S2-03] Tenant-scope OTP + WhatsApp phone routing (Tenancy/Data) | D7: [DONE][S3-03] Per-tenant AI key resolver (Billing/AI-Keys) | E7: [S4-03] Rename brain_contexts -> brain_query_cache (AI/Brain) | F7: [S5-03] Add observability (Sentry + structured logs + APM) (DevOps/Migration)
A8: [S0-04] Kill dev-mode OTP leak (Security/Auth) | B8: [DONE][S1-04] Commit real deployment config (Scale/Ops) | C8: [DONE][S2-04] Fix cross-tenant WhatsApp log leak (Tenancy/Data) | D8: [DONE][S3-04] Enforce usage quotas (402 on exceed) (Billing/AI-Keys) | E8: [S4-04] Unify /ask and /brain/agent retrieval reach (AI/Brain) | F8: [S5-04] Write + TEST a backup/restore runbook (DevOps/Migration)
A9: [S0-05] Fix WhatsApp signature bypass (Security/Auth) | B9: [DONE][S1-05] Timeout + concurrency-limit LLM calls (Scale/Ops) | C9: [DONE][S2-05] Fix unfiltered enrich_decisions fetch (Tenancy/Data) | E9: [S4-05] Extract + chunk + embed documents at ingest (AI/Brain) | F9: [S5-05] Data migration plan for schema changes above (DevOps/Migration)
A10: [S0-06] Rate-limit + captcha unauth AI endpoints (Security/Auth) | B10: [DONE][S1-06] Fix hardcoded purchase_payment key (Scale/Ops) | C10: [DONE][S2-06] Add session invalidation on logout/password-change (Tenancy/Data) | E10: [S4-06] Adopt vector search + hybrid retrieval (AI/Brain) | F10: [S5-06] Stand up CI/CD (DevOps/Migration)
A11: [S0-07] Add login rate limiting (Security/Auth) | C11: [DONE][S2-07] Add email verification + password reset (Tenancy/Data) | E11: [S4-07] Formalize a tool registry (AI/Brain) | F11: [S5-07] Define a rollback procedure (DevOps/Migration)
A12: [S0-08] Stop returning raw JWT in response body (Security/Auth) | C12: [DONE][S2-08] Fix dead contacts.kind index (Tenancy/Data) | E12: [S4-08] Add bounded planner-executor loop + native function-calling (AI/Brain) | F12: [S5-08] Move secrets to a real secrets manager (DevOps/Migration)
A13: [S0-09] Split JWT secret: tenant vs platform admin (Security/Auth) | C13: [DONE][S2-09] Fix denormalized-name staleness (Tenancy/Data) | E13: [S4-09] Add per-conversation agent memory (AI/Brain) | F13: [S5-09] Staged rollout plan (5 -> 20 -> 50 -> 100) (DevOps/Migration)
A14: [S0-10] Invalidate invite tokens after use (Security/Auth) | C14: [DONE][S2-10] Handle concurrent-registration race (Tenancy/Data) | E14: [S4-10] Expand Brain write coverage to finance/workflow/meetings (AI/Brain) | F14: [S5-10] Final go/no-go review (DevOps/Migration)
C15: [DONE][S2-11] Flag AI-operating-model generation failures (Tenancy/Data) | E15: [S4-11] Make tag vocabulary tenant/industry-configurable (AI/Brain)
C16: [DONE][S2-12] Fix 'active workflows' hardcoded terminal stages (Tenancy/Data)
A19: Card color = Priority:
A20: P0 — ship blocker
A21: P1 — before real customer
A22: P2 — hardening

Sheet Testing Plan
A1: Testing Plan — from automated tests through Alpha, Beta, and GA
A2: Every test type required before going live, sequenced by phase, plus the Alpha -> Closed Beta -> Staged Beta -> GA rollout milestones.
A4: Rollout Milestones
A5: Stage | B5: Tenant Count | C5: Duration | D5: Entry Criteria | E5: Exit Criteria / Pass Bar
A6: Internal Alpha | B6: 0 (internal only) | C6: 1-2 weeks | D6: Sprint 0 + 1 P0 Done, automated suite green | E6: Zero open P0/P1 after full manual walkthrough of every module + baseline load test
A7: Closed Beta | B7: 3-5 design partners | C7: 2-4 weeks | D7: Alpha exit met + Sprint 2 + 3 Done + backup/restore drill passed | E7: No P0 incidents, daily active usage from most partners, isolation matrix 100% pass, 1+ non-textile tenant validated
A8: Staged Open Beta | B8: 10 -> 30 -> 50 tenants | C8: 3-6 weeks (tiered) | D8: Closed Beta exit met + Sprint 5 Done | E8: SLO held at every tier, zero scheduler/cross-tenant incidents, support load manageable
A9: General Availability | B9: 100+ / self-serve | C9: Ongoing | D9: Staged Beta exit met + Go-Live Checklist 100% + go/no-go held | E9: Sustained SLA at target traffic, zero open P0s for a full monitoring cycle
A11: Detailed Test Plan — by phase
A12: Phase | B12: Test Type | C12: What It Verifies | D12: Scope / Method | E12: Entry Criteria | F12: Exit Criteria / Pass Bar | G12: Environment | H12: Linked Sprint | I12: Status | J12: Owner
A13: A | B13: Unit Testing | C13: Individual functions/handlers behave correctly in isolation (auth, RBAC, compute handlers, operating-model resolver, etc.) | D13: pytest, run on every PR (backend/pytest.ini, backend/tests/) | E13: Code written | F13: 100% of new/changed code has a passing unit test; suite green in CI | G13: Dev / CI | H13: Sprint 0-5 (continuous) | I13: In Progress — 279/279 offline suite green across 15 test files
A14: A | B14: Integration Testing | C14: Full request/response flow across routers + DB for each domain (auth, tasks, decisions, workflows, brain, ledger) | D14: pytest against a real test Mongo instance, one suite per router domain | E14: Unit suite green | F14: Every endpoint touched by Sprints 0-3 has at least one integration test; suite green | G14: Dev / CI | H14: Sprint 0-3 | I14: Not Started
A15: A | B15: Regression Testing | C15: Nothing that used to work broke as a result of this round of fixes | D15: Full automated suite re-run after each sprint merges to the branch | E15: Each sprint's tasks marked Done | F15: Zero net-new failures vs. the pre-sprint baseline run | G15: CI | H15: Every sprint | I15: In Progress — 279/279 offline suite green across 15 test files
A16: B | B16: Multi-Tenant Isolation Test Matrix | C16: No cross-tenant read/write is possible on ANY collection, endpoint, or background job | D16: Scripted test: create 2+ tenants with overlapping data (incl. same phone number per S2-03), attempt cross-tenant read/write/delete on every collection + every _ensure_owned call site from S2-01 | E16: Sprint 2 tasks Done | F16: 100% pass — zero cross-tenant access possible, incl. OTP/WhatsApp phone routing and tenant deletion completeness | G16: Staging | H16: Sprint 2 | I16: Not Started
A17: B | B17: Dynamic-Workflow Multi-Tenant Test | C17: A NON-textile tenant (e.g. restaurant/clinic) gets a correctly working approval + payment-tracking loop, not just the textile demo | D17: Onboard a synthetic non-textile tenant, run its AI-designed pipeline end to end incl. owner approval + dashboard KPIs | E17: S1-06 Done | F17: Approval gate, pending-purchases dashboard, and payment-overdue alerts all fire correctly for the non-textile pipeline | G17: Staging | H17: Sprint 1 | I17: Not Started
A18: C | B18: Security / Penetration Testing | C18: Every Sprint 0 vulnerability is actually closed, not just patched in one spot | D18: Manual + tool-assisted (OWASP ZAP or similar): CORS/CSRF exploit attempt, unauth file access, JWT tampering, WhatsApp signature bypass, brute-force login, superadmin default creds | E18: Sprint 0 tasks Done | F18: Zero exploitable findings on the Sprint 0 issue list; independent reviewer (or external pentest) sign-off | G18: Staging | H18: Sprint 0 | I18: Not Started
A19: C | B19: RBAC / Permission Audit | C19: Every role sees exactly what it should and nothing more (finance data, admin routes, brain visibility rules) | D19: Scripted test matrix: role x endpoint x expected access, incl. brain_rbac intents and document visibility rules | E19: Sprint 0-2 Done | F19: 100% pass on the role x endpoint matrix | G19: Staging | H19: Sprint 0-2 | I19: Not Started
A20: D | B20: Load / Performance Testing — Baseline | C20: Normal-traffic response times meet SLO before adding concurrency | D20: k6 or Locust against staging, single-tenant, ramping requests per endpoint | E20: Sprint 1 Done, staging live (S5-01) | F20: P95 latency within target (e.g. <500ms for reads, <3s for AI-backed endpoints) at expected steady load | G20: Staging | H20: Sprint 5 | I20: Not Started
A21: D | B21: Load Testing — Multi-Tenant Concurrency | C21: The system holds up with ~100 tenants' worth of simultaneous traffic, not just one tenant at a time | D21: k6/Locust simulating 100 tenants concurrently hitting dashboards, /ask, and voice-capture together (S5-02) | E21: Baseline load test passed | F21: No error-rate spike, no shared-LLM-key 429 cascade (validates S1-05), DB pool holds under SUMMED load | G21: Staging | H21: Sprint 5 | I21: Not Started
A22: D | B22: Spike / Burst Testing | C22: A sudden burst (e.g. many tenants' morning login + voice-capture rush) doesn't cascade into an outage | D22: Short high-intensity burst against the follow-up-scheduler window and login/OTP path | E22: Multi-tenant load test passed | F22: System recovers within target time with no dropped requests beyond configured rate limits | G22: Staging | H22: Sprint 5 | I22: Not Started
A23: D | B23: Soak / Endurance Testing | C23: No slow memory leak, connection-pool exhaustion, or gradual degradation over sustained runtime | D23: Run realistic traffic continuously for 24-48h on staging | E23: Spike test passed | F23: No degradation in latency/error-rate/memory over the full run | G23: Staging | H23: Sprint 5 | I23: Not Started
A24: D | B24: Database Query Performance at Volume | C24: Indexes actually get used and stay fast as data grows, not just at demo-tenant scale | D24: Seed staging with ~50k tasks / 10k contacts / 20k invoices across many tenants; profile the hot dashboard + /ask queries | E24: Schema fixes (S2-08, SCALE items) Done | F24: No full-collection scans on hot paths; dashboard/brief load within SLO at seeded volume | G24: Staging | H24: Sprint 1-2 | I24: Not Started
... A33: J | B33: General Availability / Self-Serve Launch | C33: The product is ready for unassisted signup at the full target scale | D33: Open self-serve signup; remove any beta gating | E33: Staged Beta exit criteria met; Go-Live Checklist 100% TRUE; final go/no-go held (S5-10) | F33: Sustained SLA at ~100-tenant traffic with no open P0s for a full monitoring cycle | G33: Production | H33: After Sprint 5 | I33: Not Started
A35: Phase key:
A36: A | B36: Automated (Unit/Integration/Regression)
A37: B | B37: Multi-Tenant Isolation
A38: C | B38: Security / Pentest
A39: D | B39: Load & Performance
A40: E | B40: Resilience / Concurrency / Chaos
A41: F | B41: Migration & Backup/DR
A42: G | B42: Internal Alpha
A43: H | B43: Closed Beta
A44: I | B44: Staged Open Beta
A45: J | B45: General Availability

Sheet RBAC & People Access
A1: RBAC & People Access — Product-Level Audit
A2: Deep audit of who-can-do-what across DecisionOS. Written product-developer style: map the current model, catalog every gap that stops the product from being sold to a multi-employee SME, ship each gap as a tracked task with tests. Companion to Sprint 2 (which fixed tenancy plumbing); this tab covers the human-facing layer on top.
A4: 1. Current-state model — what exists TODAY (verified in code)
A6: Core primitives (backend/core.py)
A7: # | B7: Primitive | C7: What it does | D7: Evidence (file:line) | E7: Verdict | I7: Notes
A8: 1 | B8: require_role(*roles) | C8: FastAPI dependency; 403 unless user.role in roles. | D8: core.py:347 | E8: OK | I8: Simple, works. Only 8 endpoints use it.
A9: 2 | B9: require_perm(perm) | C9: FastAPI dependency; 403 unless perm in user_perms(user). | D9: core.py:384 | E9: OK | I9: Only ~35 route uses; most endpoints use bare get_current_user.
A10: 3 | B10: user_perms(user) | C10: Owner -> ALL permission keys. Else user.permissions[] (if set) filtered to known keys. Else ROLE_DEFAULT_PERMS.get(role, _BASE_PERMS). | D10: core.py:364-370 | E10: WEAK | I10: Owner is a magic god-role. No way to say 'owner minus finance'.
A11: 4 | B11: _BASE_PERMS | C11: {inbox, data_input, people, workflows, tasks, brain, ask} — 7 keys. | D11: core.py:357 | E11: OK | I11: Sane starter set.
A12: 5 | B12: ROLE_DEFAULT_PERMS | C12: Maps only 'sales' -> _BASE_PERMS and 'finance' -> _BASE_PERMS | {finance, ledger}. No entry for 'production', 'operations', or any custom role — they all silently fall through to _BASE_PERMS. | D12: core.py:358-361 | E12: GAP | I12: Custom roles created via /tenant/roles have NO way to add perms without editing each user.
A13: 6 | B13: PERMISSION_KEYS | C13: 14 keys: inbox, voice_capture, data_input, people, finance, ledger, workflows, tasks, brain, ask, approvals, decisions_approve, leave_approve, team_manage. | D13: config.py:38-42 | E13: OK | I13: Reasonable granularity. But 'approvals', 'leave_approve', 'inbox', 'tasks', 'ledger' are unused as decorators.
A14: 7 | B14: ROLES vs DEFAULT_ROLES | C14: config.ROLES = [owner, sales, production, finance]. DEFAULT_ROLES = [sales, operations, finance]. Mismatch: 'production' vs 'operations'. | D14: config.py:36, 44-48 | E14: BUG | I14: Silent inconsistency — tenants get 'operations' but permission logic expects 'production'.
A16: Identity + membership model
A17: # | B17: Aspect | C17: What exists | D17: Evidence | E17: Verdict | I17: SaaS impact
A18: 1 | B18: User-to-tenant link | C18: Single `tenant_id` field on user doc. No memberships collection. | D18: team.py:143 | E18: GAP | I18: One user = one workspace. Accountants/consultants who serve multiple SMEs cannot exist as a single user account — must register N times with N emails.
A19: 2 | B19: Email uniqueness | C19: Globally unique — find_one({'email': email}) with no tenant_id in the check. | D19: team.py:122, auth.py:136, signup.py:106 | E19: GAP | I19: Blocks multi-tenant membership. Same anti-pattern we JUST fixed for phones (FIX-003-A). Email needs the same treatment.
A20: 3 | B20: Passwordless (OTP-only) users | C20: Empty password -> random hash + passwordless=True; phone >= 10 digits required; OTP-only login enforced downstream. | D20: team.py:126-136, auth.py:398/487/525 | E20: OK | I20: Good for field employees without email discipline.
A21: 4 | B21: Invite tokens | C21: invite_token + invite_expires_at (+7d) written on user creation if phone given; regeneration endpoint. | D21: team.py:154-157, 169 | E21: OK | I21: But: no 'accepted' vs 'pending' state tracking, and invited users are already listed in /users same as active ones (no visible pending state to admin).
A22: 5 | B22: Suspension flags | C22: user.suspended + tenant_suspended; both checked in get_current_user -> 403. | D22: core.py:341-342 | E22: OK | I22: But there's no session revocation on suspend — the token stays cryptographically valid until it expires (though get_current_user WILL 403 next request). Combine with FIX-003-C's jti revocation.
A23: 6 | B23: Platform admin | C23: Completely separate auth system (platform_admins collection, separate JWT type, cookie name). | D23: core.py:240-277, admin.py | E23: OK | I23: Good separation. But: platform admins can do cross-tenant reclassify/delete — no super-audit trail visible.
A25: Tenant-level custom roles
A26: # | B26: Aspect | C26: What exists | D26: Evidence | E26: Verdict | I26: SaaS impact
A27: 1 | B27: Custom role CRUD | C27: POST/rename/DELETE roles per tenant via /api/tenant/roles. Structure {key, label}. 'owner' key reserved. delete_role blocks if users still assigned. | D27: server.py:1759 (add), 1775 (rename), 1794 (delete) | E27: OK | I27: Good baseline.
A28: 2 | B28: Per-role permission map | C28: NONE. Custom roles get whatever ROLE_DEFAULT_PERMS.get(key) returns (miss -> _BASE_PERMS). | D28: core.py:369 | E28: GAP | I28: Creating a 'warehouse_manager' role and expecting it to see finance requires editing EACH user's permissions[] override. No way to say 'this ROLE always gets finance perm'.
A29: 3 | B29: Per-user permission override | C29: user.permissions[] takes precedence over role defaults. clean_perms filters to known keys. | D29: core.py:365-370, 373-381 | E29: OK | I29: Fine as an escape hatch, but shouldn't be the ONLY way to grant a permission.
A31: 2. Gap findings — ranked by severity
A32: Endpoint enforcement + data-model gaps that would embarrass us with a multi-employee SME customer.
A34: A. Endpoint enforcement gaps (from 211-endpoint sweep)
A35: # | B35: Severity | C35: Endpoint / area | D35: Current gate | E35: Why it's bad | H35: Evidence | I35: Fix task
A36: A1 | B36: P0 | C36: GET /onboarding/draft/{draft_id} + PATCH | D36: Public — no auth | E36: Any client can guess a draft ID and read/write another founder's onboarding data (industry, description, roles, phone). draft_id is a UUID but there's zero enumeration protection. | H36: onboarding.py:146, 156 | I36: RBAC-01
A37: A2 | B37: P0 | C37: POST /register | D37: Public, no CAPTCHA | E37: Anyone can spin up unlimited tenants. AI credit burn + storage cost + noisy dashboard. | H37: auth.py:96 | I37: RBAC-02
A38: A3 | B38: P0 | C38: POST /website-intel + /signup/tts + /signup/stt | D38: Public | E38: Server-side URL fetch (SSRF potential) + unauthenticated AI calls burning credits. Any attacker can drain quota. | H38: signup.py:125, tts, stt | I38: RBAC-03
A39: A4 | B39: P1 | C39: POST /workflows (create) | D39: Auth-only | E39: Any employee can create workflows. But DELETE /workflows/{id} requires owner. Asymmetric. | H39: server.py:2484 vs 2596 | I39: RBAC-04
A40: A5 | B40: P1 | C40: POST /captures/{cid}/approve|reject|reassign|patch | D40: Auth-only | E40: Approving a captured draft turns it into real workflow/task data. Should be role/perm-gated. | H40: server.py:5167-5211 | I40: RBAC-05
A41: A6 | B41: P1 | C41: POST /follow-up/run | D41: Auth-only | E41: Any employee can trigger a full tenant follow-up sweep (LLM cost, notification spam). | H41: server.py:3205 | I41: RBAC-06
A42: A7 | B42: P1 | C42: 17/17 endpoints in routers/tasks.py | D42: Auth-only | E42: Reassign, DELETE execution-plan, prioritize (LLM), bulk delete — all open to every logged-in user. Inline `role!=owner` check only on /tasks/{id} DELETE. | H42: tasks.py all | I42: RBAC-07
A43: A8 | B43: P1 | C43: POST /voice-notes text/audio + /meetings audio | D43: Auth-only | E43: Every employee can burn STT/LLM credits without any quota. Voice notes attach to any task by id. | H43: server.py:2141, 2161 | I43: RBAC-08
A44: A9 | B44: P1 | C44: POST /leaves/{id}/approve|reject|request-info | D44: Auth-only + inline helper | E44: Decorator gives no auth signal at endpoint level — reviewers reading the route can't tell what's gated. Move to require_perm('leave_approve'). | H44: team.py:322, 328, 335 | I44: RBAC-09
A45: A10 | B45: P2 | C45: POST /brain/export | D45: perm(ask) | E45: 'ask' is the QUERY permission. Export = bulk data extraction, higher privilege. | H45: brain.py:64 | I45: RBAC-10
A46: A11 | B46: P2 | C46: POST /memory (create) | D46: Auth-only | E46: Any employee can insert into shared tenant memory. No 'memory_write' permission. | H46: server.py:3264 | I46: RBAC-11
...

Sheet Go-Live Checklist
A1: Final Go-Live Checklist — before selling as SaaS at scale
A2: Set Done? to TRUE only when verified, not just coded. Row 24 gives the overall verdict.
A4: Area | B4: Checklist item | C4: Verified in | D4: Done?
A5: Security | B5: All Sprint 0 P0 items closed and verified (not just coded) | C5: Sprint 0 | D5: FALSE
A6: Security | B6: Secrets rotated out of .env into a real secrets manager | C6: Sprint 5 | D6: FALSE
A7: Scale | B7: Follow-up scheduler runs as a single external job, not in-process | C7: Sprint 1 | FIX-002-D (scheduler_locks TTL leader lock, single-fire under N replicas) | D7: TRUE
A8: Scale | B8: All file uploads route through obj_store; local-disk path removed | C8: Sprint 1 | FIX-002-E (voice notes / meetings / ledger / ingestions all obj_store) | D8: TRUE
A9: Scale | B9: Real Dockerfile/Procfile committed with pinned worker count | C9: Sprint 1 | FIX-002-F (multi-stage Docker + Procfile + .dockerignore, 25 static tests) | D9: TRUE
A10: Scale | B10: LLM calls have timeouts + a concurrency limit | C10: Sprint 1 | FIX-002-B (guarded_llm: asyncio.wait_for + semaphore) | D10: TRUE
A11: Multi-tenant | B11: Dynamic workflow approval loop works for a non-textile tenant | C11: Sprint 1 | FIX-001-A + FIX-001-F (tenant_procurement_pipeline + tenant_terminal_stages) | D11: TRUE
